<?xml version="1.0"?>
<robot name="robot_arm">

  <!-- Base Link -->
  <link name="base">
    <visual>
      <geometry>
        <cylinder radius="0.05" length="0.1"/>
      </geometry>
      <origin xyz="0 0 0" rpy="0 0 0"/>
      <material name="gray">
        <color rgba="0.5 0.5 0.5 1.0"/>
      </material>
    </visual>
  </link>

  <!-- Link 1 -->
  <link name="L1">
    <visual>
      <geometry>
        <cylinder radius="0.02" length="0.1"/>
      </geometry>
      <origin xyz="0 0 0.05" rpy="0 0 0"/>
      <material name="blue">
        <color rgba="0.0 0.0 1.0 1.0"/>
      </material>
    </visual>
  </link>

  <!-- Link 2 -->
  <link name="L2">
    <visual>
      <geometry>
        <cylinder radius="0.02" length="0.1"/>
      </geometry>
      <origin xyz="0 0 0.05" rpy="0 0 0"/>
      <material name="green">
        <color rgba="0.0 1.0 0.0 1.0"/>
      </material>
    </visual>
  </link>

  <!-- End Effector -->
  <link name="end_effector">
    <visual>
      <geometry>
        <sphere radius="0.03"/>
      </geometry>
      <origin xyz="0 0 0" rpy="0 0 0"/>
      <material name="red">
        <color rgba="1.0 0.0 0.0 1.0"/>
      </material>
    </visual>
  </link>

  <!-- Base to L1 Joint -->
  <joint name="base_to_L1" type="revolute">
    <parent link="base"/>
    <child link="L1"/>
    <origin xyz="0 0 0.05" rpy="0 0 0"/>
    <axis xyz="0 0 1"/>
    <limit lower="-3.14159" upper="3.14159" effort="10" velocity="1"/>
  </joint>

  <!-- L1 to L2 Joint -->
  <joint name="L1_to_L2" type="revolute">
    <parent link="L1"/>
    <child link="L2"/>
    <origin xyz="0 0 0.1" rpy="0 0 0"/>
    <axis xyz="0 1 0"/>
    <limit lower="-3.14159" upper="3.14159" effort="10" velocity="1"/>
  </joint>

  <!-- L2 to End Effector Joint -->
  <joint name="L2_to_end_effector" type="revolute">
    <parent link="L2"/>
    <child link="end_effector"/>
    <origin xyz="0 0 0.1" rpy="0 0 0"/>
    <axis xyz="0 1 0"/>
    <limit lower="-3.14159" upper="3.14159" effort="10" velocity="1"/>
  </joint>

</robot>